[2022-06-08 10:27:02,607] {taskinstance.py:1160} INFO - Dependencies all met for <TaskInstance: data_pipeline.tweets_to_es scheduled__2022-06-08T09:24:00+00:00 [queued]>
[2022-06-08 10:27:02,612] {taskinstance.py:1160} INFO - Dependencies all met for <TaskInstance: data_pipeline.tweets_to_es scheduled__2022-06-08T09:24:00+00:00 [queued]>
[2022-06-08 10:27:02,612] {taskinstance.py:1357} INFO - 
--------------------------------------------------------------------------------
[2022-06-08 10:27:02,612] {taskinstance.py:1358} INFO - Starting attempt 1 of 1
[2022-06-08 10:27:02,612] {taskinstance.py:1359} INFO - 
--------------------------------------------------------------------------------
[2022-06-08 10:27:02,623] {taskinstance.py:1378} INFO - Executing <Task(PythonOperator): tweets_to_es> on 2022-06-08 09:24:00+00:00
[2022-06-08 10:27:02,625] {standard_task_runner.py:52} INFO - Started process 5380 to run task
[2022-06-08 10:27:02,628] {standard_task_runner.py:79} INFO - Running: ['airflow', 'tasks', 'run', 'data_pipeline', 'tweets_to_es', 'scheduled__2022-06-08T09:24:00+00:00', '--job-id', '16', '--raw', '--subdir', 'DAGS_FOLDER/airfow_es.py', '--cfg-path', '/tmp/tmp9idcbp2g', '--error-file', '/tmp/tmp8w20knnv']
[2022-06-08 10:27:02,629] {standard_task_runner.py:80} INFO - Job 16: Subtask tweets_to_es
[2022-06-08 10:27:02,662] {task_command.py:370} INFO - Running <TaskInstance: data_pipeline.tweets_to_es scheduled__2022-06-08T09:24:00+00:00 [running]> on host oury-Tp
[2022-06-08 10:27:02,857] {taskinstance.py:1570} INFO - Exporting the following env vars:
AIRFLOW_CTX_DAG_OWNER=airflow
AIRFLOW_CTX_DAG_ID=data_pipeline
AIRFLOW_CTX_TASK_ID=tweets_to_es
AIRFLOW_CTX_EXECUTION_DATE=2022-06-08T09:24:00+00:00
AIRFLOW_CTX_TRY_NUMBER=1
AIRFLOW_CTX_DAG_RUN_ID=scheduled__2022-06-08T09:24:00+00:00
[2022-06-08 10:27:02,858] {taskinstance.py:1890} ERROR - Task failed with exception
Traceback (most recent call last):
  File "/home/oury/.local/lib/python3.10/site-packages/airflow/operators/python.py", line 171, in execute
    return_value = self.execute_callable()
  File "/home/oury/.local/lib/python3.10/site-packages/airflow/operators/python.py", line 189, in execute_callable
    return self.python_callable(*self.op_args, **self.op_kwargs)
  File "/home/oury/airflow/dags/airfow_es.py", line 54, in tweet_to_es_func
    if start_time is None:
UnboundLocalError: local variable 'start_time' referenced before assignment
[2022-06-08 10:27:02,861] {taskinstance.py:1396} INFO - Marking task as FAILED. dag_id=data_pipeline, task_id=tweets_to_es, execution_date=20220608T092400, start_date=20220608T092702, end_date=20220608T092702
[2022-06-08 10:27:02,870] {standard_task_runner.py:92} ERROR - Failed to execute job 16 for task tweets_to_es (local variable 'start_time' referenced before assignment; 5380)
[2022-06-08 10:27:02,881] {local_task_job.py:156} INFO - Task exited with return code 1
[2022-06-08 10:27:02,895] {local_task_job.py:273} INFO - 0 downstream tasks scheduled from follow-on schedule check
