[2022-06-06 09:05:09,703] {taskinstance.py:1160} INFO - Dependencies all met for <TaskInstance: data_pipeline.create_index scheduled__2022-06-05T01:50:00+00:00 [queued]>
[2022-06-06 09:05:09,710] {taskinstance.py:1160} INFO - Dependencies all met for <TaskInstance: data_pipeline.create_index scheduled__2022-06-05T01:50:00+00:00 [queued]>
[2022-06-06 09:05:09,710] {taskinstance.py:1357} INFO - 
--------------------------------------------------------------------------------
[2022-06-06 09:05:09,710] {taskinstance.py:1358} INFO - Starting attempt 1 of 1
[2022-06-06 09:05:09,710] {taskinstance.py:1359} INFO - 
--------------------------------------------------------------------------------
[2022-06-06 09:05:09,725] {taskinstance.py:1378} INFO - Executing <Task(PythonOperator): create_index> on 2022-06-05 01:50:00+00:00
[2022-06-06 09:05:09,728] {standard_task_runner.py:52} INFO - Started process 7611 to run task
[2022-06-06 09:05:09,733] {standard_task_runner.py:79} INFO - Running: ['airflow', 'tasks', 'run', 'data_pipeline', 'create_index', 'scheduled__2022-06-05T01:50:00+00:00', '--job-id', '142', '--raw', '--subdir', 'DAGS_FOLDER/airfow_es.py', '--cfg-path', '/tmp/tmpovpaksm2', '--error-file', '/tmp/tmpheijsrn4']
[2022-06-06 09:05:09,734] {standard_task_runner.py:80} INFO - Job 142: Subtask create_index
[2022-06-06 09:05:09,771] {task_command.py:370} INFO - Running <TaskInstance: data_pipeline.create_index scheduled__2022-06-05T01:50:00+00:00 [running]> on host oury-Tp
[2022-06-06 09:05:09,823] {taskinstance.py:1570} INFO - Exporting the following env vars:
AIRFLOW_CTX_DAG_OWNER=airflow
AIRFLOW_CTX_DAG_ID=data_pipeline
AIRFLOW_CTX_TASK_ID=create_index
AIRFLOW_CTX_EXECUTION_DATE=2022-06-05T01:50:00+00:00
AIRFLOW_CTX_TRY_NUMBER=1
AIRFLOW_CTX_DAG_RUN_ID=scheduled__2022-06-05T01:50:00+00:00
[2022-06-06 09:05:09,824] {taskinstance.py:1890} ERROR - Task failed with exception
Traceback (most recent call last):
  File "/home/oury/.local/lib/python3.10/site-packages/airflow/operators/python.py", line 171, in execute
    return_value = self.execute_callable()
  File "/home/oury/.local/lib/python3.10/site-packages/airflow/operators/python.py", line 189, in execute_callable
    return self.python_callable(*self.op_args, **self.op_kwargs)
TypeError: get_instance_func() missing 1 required positional argument: 'es'
[2022-06-06 09:05:09,827] {taskinstance.py:1396} INFO - Marking task as FAILED. dag_id=data_pipeline, task_id=create_index, execution_date=20220605T015000, start_date=20220606T080509, end_date=20220606T080509
[2022-06-06 09:05:09,839] {standard_task_runner.py:92} ERROR - Failed to execute job 142 for task create_index (get_instance_func() missing 1 required positional argument: 'es'; 7611)
[2022-06-06 09:05:09,864] {local_task_job.py:156} INFO - Task exited with return code 1
