[2022-06-06 09:06:33,576] {taskinstance.py:1160} INFO - Dependencies all met for <TaskInstance: data_pipeline.create_index scheduled__2022-06-05T04:10:00+00:00 [queued]>
[2022-06-06 09:06:33,584] {taskinstance.py:1160} INFO - Dependencies all met for <TaskInstance: data_pipeline.create_index scheduled__2022-06-05T04:10:00+00:00 [queued]>
[2022-06-06 09:06:33,584] {taskinstance.py:1357} INFO - 
--------------------------------------------------------------------------------
[2022-06-06 09:06:33,584] {taskinstance.py:1358} INFO - Starting attempt 1 of 1
[2022-06-06 09:06:33,584] {taskinstance.py:1359} INFO - 
--------------------------------------------------------------------------------
[2022-06-06 09:06:33,597] {taskinstance.py:1378} INFO - Executing <Task(PythonOperator): create_index> on 2022-06-05 04:10:00+00:00
[2022-06-06 09:06:33,599] {standard_task_runner.py:52} INFO - Started process 8371 to run task
[2022-06-06 09:06:33,603] {standard_task_runner.py:79} INFO - Running: ['airflow', 'tasks', 'run', 'data_pipeline', 'create_index', 'scheduled__2022-06-05T04:10:00+00:00', '--job-id', '170', '--raw', '--subdir', 'DAGS_FOLDER/airfow_es.py', '--cfg-path', '/tmp/tmp0zjbxg8c', '--error-file', '/tmp/tmp6jcbhx38']
[2022-06-06 09:06:33,604] {standard_task_runner.py:80} INFO - Job 170: Subtask create_index
[2022-06-06 09:06:33,647] {task_command.py:370} INFO - Running <TaskInstance: data_pipeline.create_index scheduled__2022-06-05T04:10:00+00:00 [running]> on host oury-Tp
[2022-06-06 09:06:33,702] {taskinstance.py:1570} INFO - Exporting the following env vars:
AIRFLOW_CTX_DAG_OWNER=airflow
AIRFLOW_CTX_DAG_ID=data_pipeline
AIRFLOW_CTX_TASK_ID=create_index
AIRFLOW_CTX_EXECUTION_DATE=2022-06-05T04:10:00+00:00
AIRFLOW_CTX_TRY_NUMBER=1
AIRFLOW_CTX_DAG_RUN_ID=scheduled__2022-06-05T04:10:00+00:00
[2022-06-06 09:06:33,703] {taskinstance.py:1890} ERROR - Task failed with exception
Traceback (most recent call last):
  File "/home/oury/.local/lib/python3.10/site-packages/airflow/operators/python.py", line 171, in execute
    return_value = self.execute_callable()
  File "/home/oury/.local/lib/python3.10/site-packages/airflow/operators/python.py", line 189, in execute_callable
    return self.python_callable(*self.op_args, **self.op_kwargs)
TypeError: get_instance_func() missing 1 required positional argument: 'es'
[2022-06-06 09:06:33,708] {taskinstance.py:1396} INFO - Marking task as FAILED. dag_id=data_pipeline, task_id=create_index, execution_date=20220605T041000, start_date=20220606T080633, end_date=20220606T080633
[2022-06-06 09:06:33,719] {standard_task_runner.py:92} ERROR - Failed to execute job 170 for task create_index (get_instance_func() missing 1 required positional argument: 'es'; 8371)
[2022-06-06 09:06:33,735] {local_task_job.py:156} INFO - Task exited with return code 1
