[2022-06-08 09:39:02,508] {taskinstance.py:1160} INFO - Dependencies all met for <TaskInstance: data_pipeline.tweets_to_es scheduled__2022-06-08T08:36:00+00:00 [queued]>
[2022-06-08 09:39:02,514] {taskinstance.py:1160} INFO - Dependencies all met for <TaskInstance: data_pipeline.tweets_to_es scheduled__2022-06-08T08:36:00+00:00 [queued]>
[2022-06-08 09:39:02,514] {taskinstance.py:1357} INFO - 
--------------------------------------------------------------------------------
[2022-06-08 09:39:02,514] {taskinstance.py:1358} INFO - Starting attempt 1 of 1
[2022-06-08 09:39:02,514] {taskinstance.py:1359} INFO - 
--------------------------------------------------------------------------------
[2022-06-08 09:39:02,526] {taskinstance.py:1378} INFO - Executing <Task(PythonOperator): tweets_to_es> on 2022-06-08 08:36:00+00:00
[2022-06-08 09:39:02,528] {standard_task_runner.py:52} INFO - Started process 20805 to run task
[2022-06-08 09:39:02,530] {standard_task_runner.py:79} INFO - Running: ['airflow', 'tasks', 'run', 'data_pipeline', 'tweets_to_es', 'scheduled__2022-06-08T08:36:00+00:00', '--job-id', '5', '--raw', '--subdir', 'DAGS_FOLDER/airfow_es.py', '--cfg-path', '/tmp/tmp87cbfuxq', '--error-file', '/tmp/tmpa40etao5']
[2022-06-08 09:39:02,531] {standard_task_runner.py:80} INFO - Job 5: Subtask tweets_to_es
[2022-06-08 09:39:02,567] {task_command.py:370} INFO - Running <TaskInstance: data_pipeline.tweets_to_es scheduled__2022-06-08T08:36:00+00:00 [running]> on host oury-Tp
[2022-06-08 09:39:02,588] {taskinstance.py:1890} ERROR - Task failed with exception
Traceback (most recent call last):
  File "/home/oury/.local/lib/python3.10/site-packages/airflow/models/taskinstance.py", line 1452, in _run_raw_task
    self._execute_task_with_callbacks(context, test_mode)
  File "/home/oury/.local/lib/python3.10/site-packages/airflow/models/taskinstance.py", line 1556, in _execute_task_with_callbacks
    task_orig = self.render_templates(context=context)
  File "/home/oury/.local/lib/python3.10/site-packages/airflow/models/taskinstance.py", line 2215, in render_templates
    rendered_task = self.task.render_template_fields(context)
  File "/home/oury/.local/lib/python3.10/site-packages/airflow/models/baseoperator.py", line 1185, in render_template_fields
    self._do_render_template_fields(self, self.template_fields, context, jinja_env, set())
  File "/home/oury/.local/lib/python3.10/site-packages/airflow/utils/session.py", line 71, in wrapper
    return func(*args, session=session, **kwargs)
  File "/home/oury/.local/lib/python3.10/site-packages/airflow/models/abstractoperator.py", line 344, in _do_render_template_fields
    rendered_content = self.render_template(
  File "/home/oury/.local/lib/python3.10/site-packages/airflow/models/abstractoperator.py", line 404, in render_template
    return {key: self.render_template(value, context, jinja_env) for key, value in value.items()}
  File "/home/oury/.local/lib/python3.10/site-packages/airflow/models/abstractoperator.py", line 404, in <dictcomp>
    return {key: self.render_template(value, context, jinja_env) for key, value in value.items()}
  File "/home/oury/.local/lib/python3.10/site-packages/airflow/models/abstractoperator.py", line 391, in render_template
    return render_template_to_string(template, context)
  File "/home/oury/.local/lib/python3.10/site-packages/airflow/utils/helpers.py", line 296, in render_template_to_string
    return render_template(template, context, native=False)
  File "/home/oury/.local/lib/python3.10/site-packages/airflow/utils/helpers.py", line 291, in render_template
    return "".join(nodes)
  File "<template>", line 12, in root
  File "/home/oury/.local/lib/python3.10/site-packages/jinja2/runtime.py", line 903, in _fail_with_undefined_error
    raise self._undefined_exception(self._undefined_message)
jinja2.exceptions.UndefinedError: 'start_time' is undefined
[2022-06-08 09:39:02,624] {taskinstance.py:1396} INFO - Marking task as FAILED. dag_id=data_pipeline, task_id=tweets_to_es, execution_date=20220608T083600, start_date=20220608T083902, end_date=20220608T083902
[2022-06-08 09:39:02,640] {standard_task_runner.py:92} ERROR - Failed to execute job 5 for task tweets_to_es ('start_time' is undefined; 20805)
[2022-06-08 09:39:02,662] {local_task_job.py:156} INFO - Task exited with return code 1
[2022-06-08 09:39:02,677] {local_task_job.py:273} INFO - 0 downstream tasks scheduled from follow-on schedule check
